package com.xcompwiz.mystcraft.world.gen.structure;

import java.util.Random;

import net.minecraft.init.Blocks;
import net.minecraft.item.ItemStack;
import net.minecraft.nbt.NBTTagCompound;
import net.minecraft.world.World;
import net.minecraft.world.gen.structure.StructureBoundingBox;
import net.minecraftforge.common.ChestGenHooks;

import com.xcompwiz.mystcraft.api.MystObjects;
import com.xcompwiz.mystcraft.data.ModBlocks;
import com.xcompwiz.mystcraft.page.Page;
import com.xcompwiz.mystcraft.symbol.IAgeSymbol;
import com.xcompwiz.mystcraft.symbol.SymbolManager;
import com.xcompwiz.mystcraft.tileentity.TileEntityLectern;

public class ComponentScatteredFeatureSmallLibrary extends ComponentScatteredFeatureMyst {
	private boolean					hasMadeChest;

	private boolean[]				lecternGenned	= new boolean[5];
	private static final int[][]	lecternCoords	= new int[][] { { 6, 2, 2 }, { 8, 2, 4 }, { 8, 2, 5 }, { 8, 2, 6 }, { 6, 2, 8 } };
	private static final int[][]	lecternTargs	= new int[][] { { 6, 3 }, { 7, 4 }, { 7, 5 }, { 7, 6 }, { 6, 7 } };

	public ComponentScatteredFeatureSmallLibrary() {}

	public ComponentScatteredFeatureSmallLibrary(Random par1Random, int x, int z) {
		super(par1Random, x, 64, z, 10, 10, 10);
	}

	@Override
	protected void func_143012_a(NBTTagCompound nbttagcompound) {
		super.func_143012_a(nbttagcompound);

		nbttagcompound.setBoolean("Chest", this.hasMadeChest);
		for (int i = 0; i < lecternGenned.length; ++i) {
			nbttagcompound.setBoolean("hasPlacedLectern" + i, this.lecternGenned[i]);
		}
	}

	@Override
	protected void func_143011_b(NBTTagCompound nbttagcompound) {
		super.func_143011_b(nbttagcompound);

		this.hasMadeChest = nbttagcompound.getBoolean("Chest");
		for (int i = 0; i < lecternGenned.length; ++i) {
			if (!nbttagcompound.hasKey("hasPlacedLectern" + i)) continue;
			lecternGenned[i] = nbttagcompound.getBoolean("hasPlacedLectern" + i);
		}
	}

	/**
	 * second Part of Structure generating, this for example places Spiderwebs, Mob Spawners, it closes Mineshafts at the end, it adds Fences...
	 */
	@Override
	public boolean addComponentParts(World worldObj, Random rand, StructureBoundingBox boundingbox) {
		if (!this.shouldBuildHere(worldObj, boundingbox, 0)) return false;
		//LoggerUtils.info("Generating Library at %d %d %d", boundingbox.minX, boundingbox.minY, boundingbox.minZ);

		// 0 - Towards front
		// 1 - Towards back
		// 2 - Towards Left
		// 3 - Towards Right
		// 4 - Up Towards Right
		// 5 - Up Towards Left
		// 6 - Up Towards Front
		// 7 - Up Towards Back
		int var0 = this.getMetadataWithOffset(Blocks.sandstone_stairs, 0); // Front - LOCK
		int var1 = this.getMetadataWithOffset(Blocks.sandstone_stairs, 1); // Back - LOCK
		int var2 = this.getMetadataWithOffset(Blocks.sandstone_stairs, 3); // Right - LOCK
		int var3 = this.getMetadataWithOffset(Blocks.sandstone_stairs, 2); // Left - LOCK
		int var4 = var0 | 0x04; // this.getMetadataWithOffset(Blocks.stairsSandStone, 4); // UpFront
		int var5 = var1 | 0x04; // this.getMetadataWithOffset(Blocks.stairsSandStone, 5);
		int var6 = var2 | 0x04; // this.getMetadataWithOffset(Blocks.stairsSandStone, 7); // UpRight - LOCK
		int var7 = var3 | 0x04; // this.getMetadataWithOffset(Blocks.stairsSandStone, 6);
		placeBlockAtCurrentPosition(worldObj, Blocks.air, 0, 0, 1, 3, boundingbox);
		placeBlockAtCurrentPosition(worldObj, Blocks.air, 0, 0, 1, 4, boundingbox);
		placeBlockAtCurrentPosition(worldObj, Blocks.air, 0, 0, 1, 5, boundingbox);
		placeBlockAtCurrentPosition(worldObj, Blocks.air, 0, 0, 1, 6, boundingbox);
		placeBlockAtCurrentPosition(worldObj, Blocks.air, 0, 0, 1, 7, boundingbox);
		placeBlockAtCurrentPosition(worldObj, Blocks.air, 0, 0, 2, 3, boundingbox);
		placeBlockAtCurrentPosition(worldObj, Blocks.air, 0, 0, 2, 4, boundingbox);
		placeBlockAtCurrentPosition(worldObj, Blocks.air, 0, 0, 2, 5, boundingbox);
		placeBlockAtCurrentPosition(worldObj, Blocks.air, 0, 0, 2, 6, boundingbox);
		placeBlockAtCurrentPosition(worldObj, Blocks.air, 0, 0, 2, 7, boundingbox);
		placeBlockAtCurrentPosition(worldObj, Blocks.air, 0, 0, 3, 3, boundingbox);
		placeBlockAtCurrentPosition(worldObj, Blocks.air, 0, 0, 3, 4, boundingbox);
		placeBlockAtCurrentPosition(worldObj, Blocks.air, 0, 0, 3, 5, boundingbox);
		placeBlockAtCurrentPosition(worldObj, Blocks.air, 0, 0, 3, 6, boundingbox);
		placeBlockAtCurrentPosition(worldObj, Blocks.air, 0, 0, 3, 7, boundingbox);
		placeBlockAtCurrentPosition(worldObj, Blocks.air, 0, 1, 1, 3, boundingbox);
		placeBlockAtCurrentPosition(worldObj, Blocks.air, 0, 1, 1, 5, boundingbox);
		placeBlockAtCurrentPosition(worldObj, Blocks.air, 0, 1, 1, 7, boundingbox);
		placeBlockAtCurrentPosition(worldObj, Blocks.air, 0, 1, 2, 3, boundingbox);
		placeBlockAtCurrentPosition(worldObj, Blocks.air, 0, 1, 2, 5, boundingbox);
		placeBlockAtCurrentPosition(worldObj, Blocks.air, 0, 1, 2, 7, boundingbox);
		placeBlockAtCurrentPosition(worldObj, Blocks.air, 0, 1, 3, 3, boundingbox);
		placeBlockAtCurrentPosition(worldObj, Blocks.air, 0, 1, 3, 5, boundingbox);
		placeBlockAtCurrentPosition(worldObj, Blocks.air, 0, 1, 3, 7, boundingbox);
		placeBlockAtCurrentPosition(worldObj, Blocks.air, 0, 2, 1, 3, boundingbox);
		placeBlockAtCurrentPosition(worldObj, Blocks.air, 0, 2, 1, 4, boundingbox);
		placeBlockAtCurrentPosition(worldObj, Blocks.air, 0, 2, 1, 5, boundingbox);
		placeBlockAtCurrentPosition(worldObj, Blocks.air, 0, 2, 1, 6, boundingbox);
		placeBlockAtCurrentPosition(worldObj, Blocks.air, 0, 2, 1, 7, boundingbox);
		placeBlockAtCurrentPosition(worldObj, Blocks.air, 0, 2, 2, 3, boundingbox);
		placeBlockAtCurrentPosition(worldObj, Blocks.air, 0, 2, 2, 4, boundingbox);
		placeBlockAtCurrentPosition(worldObj, Blocks.air, 0, 2, 2, 5, boundingbox);
		placeBlockAtCurrentPosition(worldObj, Blocks.air, 0, 2, 2, 6, boundingbox);
		placeBlockAtCurrentPosition(worldObj, Blocks.air, 0, 2, 2, 7, boundingbox);
		placeBlockAtCurrentPosition(worldObj, Blocks.air, 0, 2, 3, 3, boundingbox);
		placeBlockAtCurrentPosition(worldObj, Blocks.air, 0, 2, 3, 4, boundingbox);
		placeBlockAtCurrentPosition(worldObj, Blocks.air, 0, 2, 3, 5, boundingbox);
		placeBlockAtCurrentPosition(worldObj, Blocks.air, 0, 2, 3, 6, boundingbox);
		placeBlockAtCurrentPosition(worldObj, Blocks.air, 0, 2, 3, 7, boundingbox);
		placeBlockAtCurrentPosition(worldObj, Blocks.air, 0, 3, 1, 5, boundingbox);
		placeBlockAtCurrentPosition(worldObj, Blocks.air, 0, 3, 2, 5, boundingbox);
		placeBlockAtCurrentPosition(worldObj, Blocks.air, 0, 4, 1, 4, boundingbox);
		placeBlockAtCurrentPosition(worldObj, Blocks.air, 0, 4, 1, 5, boundingbox);
		placeBlockAtCurrentPosition(worldObj, Blocks.air, 0, 4, 1, 6, boundingbox);
		placeBlockAtCurrentPosition(worldObj, Blocks.air, 0, 4, 2, 4, boundingbox);
		placeBlockAtCurrentPosition(worldObj, Blocks.air, 0, 4, 2, 5, boundingbox);
		placeBlockAtCurrentPosition(worldObj, Blocks.air, 0, 4, 2, 6, boundingbox);
		placeBlockAtCurrentPosition(worldObj, Blocks.air, 0, 4, 3, 4, boundingbox);
		placeBlockAtCurrentPosition(worldObj, Blocks.air, 0, 4, 3, 5, boundingbox);
		placeBlockAtCurrentPosition(worldObj, Blocks.air, 0, 4, 3, 6, boundingbox);
		placeBlockAtCurrentPosition(worldObj, Blocks.air, 0, 4, 4, 4, boundingbox);
		placeBlockAtCurrentPosition(worldObj, Blocks.air, 0, 4, 4, 5, boundingbox);
		placeBlockAtCurrentPosition(worldObj, Blocks.air, 0, 4, 4, 6, boundingbox);
		placeBlockAtCurrentPosition(worldObj, Blocks.air, 0, 4, 5, 3, boundingbox);
		placeBlockAtCurrentPosition(worldObj, Blocks.air, 0, 4, 5, 4, boundingbox);
		placeBlockAtCurrentPosition(worldObj, Blocks.air, 0, 4, 5, 5, boundingbox);
		placeBlockAtCurrentPosition(worldObj, Blocks.air, 0, 4, 5, 6, boundingbox);
		placeBlockAtCurrentPosition(worldObj, Blocks.air, 0, 4, 5, 7, boundingbox);
		placeBlockAtCurrentPosition(worldObj, Blocks.air, 0, 4, 5, 8, boundingbox);
		placeBlockAtCurrentPosition(worldObj, Blocks.air, 0, 4, 6, 7, boundingbox);
		placeBlockAtCurrentPosition(worldObj, Blocks.air, 0, 4, 6, 8, boundingbox);
		placeBlockAtCurrentPosition(worldObj, Blocks.air, 0, 5, 1, 3, boundingbox);
		placeBlockAtCurrentPosition(worldObj, Blocks.air, 0, 5, 1, 4, boundingbox);
		placeBlockAtCurrentPosition(worldObj, Blocks.air, 0, 5, 1, 5, boundingbox);
		placeBlockAtCurrentPosition(worldObj, Blocks.air, 0, 5, 1, 6, boundingbox);
		placeBlockAtCurrentPosition(worldObj, Blocks.air, 0, 5, 1, 7, boundingbox);
		placeBlockAtCurrentPosition(worldObj, Blocks.air, 0, 5, 2, 3, boundingbox);
		placeBlockAtCurrentPosition(worldObj, Blocks.air, 0, 5, 2, 4, boundingbox);
		placeBlockAtCurrentPosition(worldObj, Blocks.air, 0, 5, 2, 5, boundingbox);
		placeBlockAtCurrentPosition(worldObj, Blocks.air, 0, 5, 2, 6, boundingbox);
		placeBlockAtCurrentPosition(worldObj, Blocks.air, 0, 5, 2, 7, boundingbox);
		placeBlockAtCurrentPosition(worldObj, Blocks.air, 0, 5, 3, 3, boundingbox);
		placeBlockAtCurrentPosition(worldObj, Blocks.air, 0, 5, 3, 4, boundingbox);
		placeBlockAtCurrentPosition(worldObj, Blocks.air, 0, 5, 3, 5, boundingbox);
		placeBlockAtCurrentPosition(worldObj, Blocks.air, 0, 5, 3, 6, boundingbox);
		placeBlockAtCurrentPosition(worldObj, Blocks.air, 0, 5, 3, 7, boundingbox);
		placeBlockAtCurrentPosition(worldObj, Blocks.air, 0, 5, 4, 3, boundingbox);
		placeBlockAtCurrentPosition(worldObj, Blocks.air, 0, 5, 4, 4, boundingbox);
		placeBlockAtCurrentPosition(worldObj, Blocks.air, 0, 5, 4, 5, boundingbox);
		placeBlockAtCurrentPosition(worldObj, Blocks.air, 0, 5, 4, 6, boundingbox);
		placeBlockAtCurrentPosition(worldObj, Blocks.air, 0, 5, 4, 7, boundingbox);
		placeBlockAtCurrentPosition(worldObj, Blocks.air, 0, 5, 5, 3, boundingbox);
		placeBlockAtCurrentPosition(worldObj, Blocks.air, 0, 5, 5, 4, boundingbox);
		placeBlockAtCurrentPosition(worldObj, Blocks.air, 0, 5, 5, 5, boundingbox);
		placeBlockAtCurrentPosition(worldObj, Blocks.air, 0, 5, 5, 6, boundingbox);
		placeBlockAtCurrentPosition(worldObj, Blocks.air, 0, 5, 5, 7, boundingbox);
		placeBlockAtCurrentPosition(worldObj, Blocks.air, 0, 5, 6, 5, boundingbox);
		placeBlockAtCurrentPosition(worldObj, Blocks.air, 0, 5, 6, 6, boundingbox);
		placeBlockAtCurrentPosition(worldObj, Blocks.air, 0, 5, 6, 7, boundingbox);
		placeBlockAtCurrentPosition(worldObj, Blocks.air, 0, 5, 6, 8, boundingbox);
		placeBlockAtCurrentPosition(worldObj, Blocks.air, 0, 6, 1, 3, boundingbox);
		placeBlockAtCurrentPosition(worldObj, Blocks.air, 0, 6, 1, 4, boundingbox);
		placeBlockAtCurrentPosition(worldObj, Blocks.air, 0, 6, 1, 5, boundingbox);
		placeBlockAtCurrentPosition(worldObj, Blocks.air, 0, 6, 1, 6, boundingbox);
		placeBlockAtCurrentPosition(worldObj, Blocks.air, 0, 6, 1, 7, boundingbox);
		placeBlockAtCurrentPosition(worldObj, Blocks.air, 0, 6, 2, 3, boundingbox);
		placeBlockAtCurrentPosition(worldObj, Blocks.air, 0, 6, 2, 4, boundingbox);
		placeBlockAtCurrentPosition(worldObj, Blocks.air, 0, 6, 2, 5, boundingbox);
		placeBlockAtCurrentPosition(worldObj, Blocks.air, 0, 6, 2, 6, boundingbox);
		placeBlockAtCurrentPosition(worldObj, Blocks.air, 0, 6, 2, 7, boundingbox);
		placeBlockAtCurrentPosition(worldObj, Blocks.air, 0, 6, 3, 3, boundingbox);
		placeBlockAtCurrentPosition(worldObj, Blocks.air, 0, 6, 3, 4, boundingbox);
		placeBlockAtCurrentPosition(worldObj, Blocks.air, 0, 6, 3, 5, boundingbox);
		placeBlockAtCurrentPosition(worldObj, Blocks.air, 0, 6, 3, 6, boundingbox);
		placeBlockAtCurrentPosition(worldObj, Blocks.air, 0, 6, 3, 7, boundingbox);
		placeBlockAtCurrentPosition(worldObj, Blocks.air, 0, 6, 4, 3, boundingbox);
		placeBlockAtCurrentPosition(worldObj, Blocks.air, 0, 6, 4, 4, boundingbox);
		placeBlockAtCurrentPosition(worldObj, Blocks.air, 0, 6, 4, 5, boundingbox);
		placeBlockAtCurrentPosition(worldObj, Blocks.air, 0, 6, 4, 6, boundingbox);
		placeBlockAtCurrentPosition(worldObj, Blocks.air, 0, 6, 4, 7, boundingbox);
		placeBlockAtCurrentPosition(worldObj, Blocks.air, 0, 6, 5, 2, boundingbox);
		placeBlockAtCurrentPosition(worldObj, Blocks.air, 0, 6, 5, 3, boundingbox);
		placeBlockAtCurrentPosition(worldObj, Blocks.air, 0, 6, 5, 4, boundingbox);
		placeBlockAtCurrentPosition(worldObj, Blocks.air, 0, 6, 5, 5, boundingbox);
		placeBlockAtCurrentPosition(worldObj, Blocks.air, 0, 6, 5, 6, boundingbox);
		placeBlockAtCurrentPosition(worldObj, Blocks.air, 0, 6, 5, 7, boundingbox);
		placeBlockAtCurrentPosition(worldObj, Blocks.air, 0, 6, 6, 4, boundingbox);
		placeBlockAtCurrentPosition(worldObj, Blocks.air, 0, 6, 6, 5, boundingbox);
		placeBlockAtCurrentPosition(worldObj, Blocks.air, 0, 6, 6, 6, boundingbox);
		placeBlockAtCurrentPosition(worldObj, Blocks.air, 0, 7, 1, 3, boundingbox);
		placeBlockAtCurrentPosition(worldObj, Blocks.air, 0, 7, 1, 4, boundingbox);
		placeBlockAtCurrentPosition(worldObj, Blocks.air, 0, 7, 1, 5, boundingbox);
		placeBlockAtCurrentPosition(worldObj, Blocks.air, 0, 7, 1, 6, boundingbox);
		placeBlockAtCurrentPosition(worldObj, Blocks.air, 0, 7, 1, 7, boundingbox);
		placeBlockAtCurrentPosition(worldObj, Blocks.air, 0, 7, 2, 3, boundingbox);
		placeBlockAtCurrentPosition(worldObj, Blocks.air, 0, 7, 2, 4, boundingbox);
		placeBlockAtCurrentPosition(worldObj, Blocks.air, 0, 7, 2, 5, boundingbox);
		placeBlockAtCurrentPosition(worldObj, Blocks.air, 0, 7, 2, 6, boundingbox);
		placeBlockAtCurrentPosition(worldObj, Blocks.air, 0, 7, 2, 7, boundingbox);
		placeBlockAtCurrentPosition(worldObj, Blocks.air, 0, 7, 3, 3, boundingbox);
		placeBlockAtCurrentPosition(worldObj, Blocks.air, 0, 7, 3, 4, boundingbox);
		placeBlockAtCurrentPosition(worldObj, Blocks.air, 0, 7, 3, 5, boundingbox);
		placeBlockAtCurrentPosition(worldObj, Blocks.air, 0, 7, 3, 6, boundingbox);
		placeBlockAtCurrentPosition(worldObj, Blocks.air, 0, 7, 3, 7, boundingbox);
		placeBlockAtCurrentPosition(worldObj, Blocks.air, 0, 7, 4, 3, boundingbox);
		placeBlockAtCurrentPosition(worldObj, Blocks.air, 0, 7, 4, 4, boundingbox);
		placeBlockAtCurrentPosition(worldObj, Blocks.air, 0, 7, 4, 5, boundingbox);
		placeBlockAtCurrentPosition(worldObj, Blocks.air, 0, 7, 4, 6, boundingbox);
		placeBlockAtCurrentPosition(worldObj, Blocks.air, 0, 7, 4, 7, boundingbox);
		placeBlockAtCurrentPosition(worldObj, Blocks.air, 0, 7, 5, 2, boundingbox);
		placeBlockAtCurrentPosition(worldObj, Blocks.air, 0, 7, 5, 3, boundingbox);
		placeBlockAtCurrentPosition(worldObj, Blocks.air, 0, 7, 5, 4, boundingbox);
		placeBlockAtCurrentPosition(worldObj, Blocks.air, 0, 7, 5, 5, boundingbox);
		placeBlockAtCurrentPosition(worldObj, Blocks.air, 0, 7, 5, 6, boundingbox);
		placeBlockAtCurrentPosition(worldObj, Blocks.air, 0, 7, 5, 7, boundingbox);
		placeBlockAtCurrentPosition(worldObj, Blocks.air, 0, 7, 6, 3, boundingbox);
		placeBlockAtCurrentPosition(worldObj, Blocks.air, 0, 7, 6, 4, boundingbox);
		placeBlockAtCurrentPosition(worldObj, Blocks.air, 0, 7, 6, 5, boundingbox);
		placeBlockAtCurrentPosition(worldObj, Blocks.air, 0, 7, 6, 6, boundingbox);
		placeBlockAtCurrentPosition(worldObj, Blocks.air, 0, 7, 6, 7, boundingbox);
		placeBlockAtCurrentPosition(worldObj, Blocks.air, 0, 8, 5, 7, boundingbox);
		placeBlockAtCurrentPosition(worldObj, Blocks.air, 0, 8, 6, 2, boundingbox);
		placeBlockAtCurrentPosition(worldObj, Blocks.air, 0, 8, 6, 4, boundingbox);
		placeBlockAtCurrentPosition(worldObj, Blocks.air, 0, 8, 6, 5, boundingbox);
		placeBlockAtCurrentPosition(worldObj, Blocks.air, 0, 8, 6, 7, boundingbox);
		placeBlockAtCurrentPosition(worldObj, Blocks.air, 0, 8, 6, 8, boundingbox);
		placeBlockAtCurrentPosition(worldObj, Blocks.bookshelf, 0, 4, 3, 7, boundingbox);
		placeBlockAtCurrentPosition(worldObj, Blocks.bookshelf, 0, 4, 1, 3, boundingbox);
		placeBlockAtCurrentPosition(worldObj, Blocks.bookshelf, 0, 4, 1, 7, boundingbox);
		placeBlockAtCurrentPosition(worldObj, Blocks.bookshelf, 0, 4, 2, 3, boundingbox);
		placeBlockAtCurrentPosition(worldObj, Blocks.bookshelf, 0, 4, 2, 7, boundingbox);
		placeBlockAtCurrentPosition(worldObj, Blocks.bookshelf, 0, 4, 3, 3, boundingbox);
		placeBlockAtCurrentPosition(worldObj, Blocks.bookshelf, 0, 4, 4, 3, boundingbox);
		placeBlockAtCurrentPosition(worldObj, Blocks.bookshelf, 0, 4, 4, 7, boundingbox);
		placeBlockAtCurrentPosition(worldObj, Blocks.bookshelf, 0, 5, 1, 2, boundingbox);
		placeBlockAtCurrentPosition(worldObj, Blocks.bookshelf, 0, 5, 1, 8, boundingbox);
		placeBlockAtCurrentPosition(worldObj, Blocks.bookshelf, 0, 5, 2, 2, boundingbox);
		placeBlockAtCurrentPosition(worldObj, Blocks.bookshelf, 0, 5, 2, 8, boundingbox);
		placeBlockAtCurrentPosition(worldObj, Blocks.bookshelf, 0, 5, 3, 2, boundingbox);
		placeBlockAtCurrentPosition(worldObj, Blocks.bookshelf, 0, 5, 3, 8, boundingbox);
		placeBlockAtCurrentPosition(worldObj, Blocks.bookshelf, 0, 5, 4, 2, boundingbox);
		placeBlockAtCurrentPosition(worldObj, Blocks.bookshelf, 0, 5, 4, 8, boundingbox);
		placeBlockAtCurrentPosition(worldObj, Blocks.bookshelf, 0, 6, 1, 2, boundingbox);
		placeBlockAtCurrentPosition(worldObj, Blocks.bookshelf, 0, 6, 1, 8, boundingbox);
		placeBlockAtCurrentPosition(worldObj, Blocks.bookshelf, 0, 6, 3, 2, boundingbox);
		placeBlockAtCurrentPosition(worldObj, Blocks.bookshelf, 0, 6, 3, 8, boundingbox);
		placeBlockAtCurrentPosition(worldObj, Blocks.bookshelf, 0, 6, 4, 2, boundingbox);
		placeBlockAtCurrentPosition(worldObj, Blocks.bookshelf, 0, 6, 4, 8, boundingbox);
		placeBlockAtCurrentPosition(worldObj, Blocks.bookshelf, 0, 7, 1, 2, boundingbox);
		placeBlockAtCurrentPosition(worldObj, Blocks.bookshelf, 0, 7, 1, 8, boundingbox);
		placeBlockAtCurrentPosition(worldObj, Blocks.bookshelf, 0, 7, 2, 2, boundingbox);
		placeBlockAtCurrentPosition(worldObj, Blocks.bookshelf, 0, 7, 2, 8, boundingbox);
		placeBlockAtCurrentPosition(worldObj, Blocks.bookshelf, 0, 7, 3, 2, boundingbox);
		placeBlockAtCurrentPosition(worldObj, Blocks.bookshelf, 0, 7, 3, 8, boundingbox);
		placeBlockAtCurrentPosition(worldObj, Blocks.bookshelf, 0, 7, 4, 2, boundingbox);
		placeBlockAtCurrentPosition(worldObj, Blocks.bookshelf, 0, 7, 4, 8, boundingbox);
		placeBlockAtCurrentPosition(worldObj, Blocks.bookshelf, 0, 8, 1, 3, boundingbox);
		placeBlockAtCurrentPosition(worldObj, Blocks.bookshelf, 0, 8, 1, 4, boundingbox);
		placeBlockAtCurrentPosition(worldObj, Blocks.bookshelf, 0, 8, 1, 5, boundingbox);
		placeBlockAtCurrentPosition(worldObj, Blocks.bookshelf, 0, 8, 1, 6, boundingbox);
		placeBlockAtCurrentPosition(worldObj, Blocks.bookshelf, 0, 8, 1, 7, boundingbox);
		placeBlockAtCurrentPosition(worldObj, Blocks.bookshelf, 0, 8, 2, 3, boundingbox);
		placeBlockAtCurrentPosition(worldObj, Blocks.bookshelf, 0, 8, 2, 7, boundingbox);
		placeBlockAtCurrentPosition(worldObj, Blocks.bookshelf, 0, 8, 3, 3, boundingbox);
		placeBlockAtCurrentPosition(worldObj, Blocks.bookshelf, 0, 8, 3, 4, boundingbox);
		placeBlockAtCurrentPosition(worldObj, Blocks.bookshelf, 0, 8, 3, 5, boundingbox);
		placeBlockAtCurrentPosition(worldObj, Blocks.bookshelf, 0, 8, 3, 6, boundingbox);
		placeBlockAtCurrentPosition(worldObj, Blocks.bookshelf, 0, 8, 3, 7, boundingbox);
		placeBlockAtCurrentPosition(worldObj, Blocks.bookshelf, 0, 8, 4, 3, boundingbox);
		placeBlockAtCurrentPosition(worldObj, Blocks.bookshelf, 0, 8, 4, 4, boundingbox);
		placeBlockAtCurrentPosition(worldObj, Blocks.bookshelf, 0, 8, 4, 5, boundingbox);
		placeBlockAtCurrentPosition(worldObj, Blocks.bookshelf, 0, 8, 4, 6, boundingbox);
		placeBlockAtCurrentPosition(worldObj, Blocks.bookshelf, 0, 8, 4, 7, boundingbox);
		placeBlockAtCurrentPosition(worldObj, Blocks.cobblestone, 0, 1, 0, 4, boundingbox);
		placeBlockAtCurrentPosition(worldObj, Blocks.cobblestone, 0, 1, 0, 5, boundingbox);
		placeBlockAtCurrentPosition(worldObj, Blocks.cobblestone, 0, 1, 0, 6, boundingbox);
		placeBlockAtCurrentPosition(worldObj, Blocks.cobblestone, 0, 2, 0, 4, boundingbox);
		placeBlockAtCurrentPosition(worldObj, Blocks.cobblestone, 0, 2, 0, 5, boundingbox);
		placeBlockAtCurrentPosition(worldObj, Blocks.cobblestone, 0, 2, 0, 6, boundingbox);
		placeBlockAtCurrentPosition(worldObj, Blocks.cobblestone, 0, 2, 4, 4, boundingbox);
		placeBlockAtCurrentPosition(worldObj, Blocks.cobblestone, 0, 2, 4, 5, boundingbox);
		placeBlockAtCurrentPosition(worldObj, Blocks.cobblestone, 0, 2, 4, 6, boundingbox);
		placeBlockAtCurrentPosition(worldObj, Blocks.cobblestone, 0, 2, 5, 5, boundingbox);
		placeBlockAtCurrentPosition(worldObj, Blocks.cobblestone, 0, 3, 0, 1, boundingbox);
		placeBlockAtCurrentPosition(worldObj, Blocks.cobblestone, 0, 3, 0, 2, boundingbox);
		placeBlockAtCurrentPosition(worldObj, Blocks.cobblestone, 0, 3, 0, 3, boundingbox);
		placeBlockAtCurrentPosition(worldObj, Blocks.cobblestone, 0, 3, 0, 4, boundingbox);
		placeBlockAtCurrentPosition(worldObj, Blocks.cobblestone, 0, 3, 0, 5, boundingbox);
		placeBlockAtCurrentPosition(worldObj, Blocks.cobblestone, 0, 3, 0, 6, boundingbox);
		placeBlockAtCurrentPosition(worldObj, Blocks.cobblestone, 0, 3, 0, 7, boundingbox);
		placeBlockAtCurrentPosition(worldObj, Blocks.cobblestone, 0, 3, 0, 8, boundingbox);
		placeBlockAtCurrentPosition(worldObj, Blocks.cobblestone, 0, 3, 0, 9, boundingbox);
		placeBlockAtCurrentPosition(worldObj, Blocks.cobblestone, 0, 3, 1, 1, boundingbox);
		placeBlockAtCurrentPosition(worldObj, Blocks.cobblestone, 0, 3, 1, 2, boundingbox);
		placeBlockAtCurrentPosition(worldObj, Blocks.cobblestone, 0, 3, 1, 3, boundingbox);
		placeBlockAtCurrentPosition(worldObj, Blocks.cobblestone, 0, 3, 1, 4, boundingbox);
		placeBlockAtCurrentPosition(worldObj, Blocks.cobblestone, 0, 3, 1, 6, boundingbox);
		placeBlockAtCurrentPosition(worldObj, Blocks.cobblestone, 0, 3, 1, 7, boundingbox);
		placeBlockAtCurrentPosition(worldObj, Blocks.cobblestone, 0, 3, 1, 8, boundingbox);
		placeBlockAtCurrentPosition(worldObj, Blocks.cobblestone, 0, 3, 1, 9, boundingbox);
		placeBlockAtCurrentPosition(worldObj, Blocks.cobblestone, 0, 3, 2, 1, boundingbox);
		placeBlockAtCurrentPosition(worldObj, Blocks.cobblestone, 0, 3, 2, 2, boundingbox);
		placeBlockAtCurrentPosition(worldObj, Blocks.cobblestone, 0, 3, 2, 3, boundingbox);
		placeBlockAtCurrentPosition(worldObj, Blocks.cobblestone, 0, 3, 2, 4, boundingbox);
		placeBlockAtCurrentPosition(worldObj, Blocks.cobblestone, 0, 3, 2, 6, boundingbox);
		placeBlockAtCurrentPosition(worldObj, Blocks.cobblestone, 0, 3, 2, 7, boundingbox);
		placeBlockAtCurrentPosition(worldObj, Blocks.cobblestone, 0, 3, 2, 8, boundingbox);
		placeBlockAtCurrentPosition(worldObj, Blocks.cobblestone, 0, 3, 2, 9, boundingbox);
		placeBlockAtCurrentPosition(worldObj, Blocks.cobblestone, 0, 3, 3, 1, boundingbox);
		placeBlockAtCurrentPosition(worldObj, Blocks.cobblestone, 0, 3, 3, 2, boundingbox);
		placeBlockAtCurrentPosition(worldObj, Blocks.cobblestone, 0, 3, 3, 3, boundingbox);
		placeBlockAtCurrentPosition(worldObj, Blocks.cobblestone, 0, 3, 3, 4, boundingbox);
		placeBlockAtCurrentPosition(worldObj, Blocks.cobblestone, 0, 3, 3, 6, boundingbox);
		placeBlockAtCurrentPosition(worldObj, Blocks.cobblestone, 0, 3, 3, 7, boundingbox);
		placeBlockAtCurrentPosition(worldObj, Blocks.cobblestone, 0, 3, 3, 8, boundingbox);
		placeBlockAtCurrentPosition(worldObj, Blocks.cobblestone, 0, 3, 3, 9, boundingbox);
		placeBlockAtCurrentPosition(worldObj, Blocks.cobblestone, 0, 3, 4, 1, boundingbox);
		placeBlockAtCurrentPosition(worldObj, Blocks.cobblestone, 0, 3, 4, 2, boundingbox);
		placeBlockAtCurrentPosition(worldObj, Blocks.cobblestone, 0, 3, 4, 3, boundingbox);
		placeBlockAtCurrentPosition(worldObj, Blocks.cobblestone, 0, 3, 4, 4, boundingbox);
		placeBlockAtCurrentPosition(worldObj, Blocks.cobblestone, 0, 3, 4, 5, boundingbox);
		placeBlockAtCurrentPosition(worldObj, Blocks.cobblestone, 0, 3, 4, 6, boundingbox);
		placeBlockAtCurrentPosition(worldObj, Blocks.cobblestone, 0, 3, 4, 7, boundingbox);
		placeBlockAtCurrentPosition(worldObj, Blocks.cobblestone, 0, 3, 4, 8, boundingbox);
		placeBlockAtCurrentPosition(worldObj, Blocks.cobblestone, 0, 3, 4, 9, boundingbox);
		placeBlockAtCurrentPosition(worldObj, Blocks.cobblestone, 0, 3, 5, 1, boundingbox);
		placeBlockAtCurrentPosition(worldObj, Blocks.cobblestone, 0, 3, 5, 2, boundingbox);
		placeBlockAtCurrentPosition(worldObj, Blocks.cobblestone, 0, 3, 5, 3, boundingbox);
		placeBlockAtCurrentPosition(worldObj, Blocks.cobblestone, 0, 3, 5, 4, boundingbox);
		placeBlockAtCurrentPosition(worldObj, Blocks.cobblestone, 0, 3, 5, 5, boundingbox);
		placeBlockAtCurrentPosition(worldObj, Blocks.cobblestone, 0, 3, 5, 6, boundingbox);
		placeBlockAtCurrentPosition(worldObj, Blocks.cobblestone, 0, 3, 5, 7, boundingbox);
		placeBlockAtCurrentPosition(worldObj, Blocks.cobblestone, 0, 3, 5, 8, boundingbox);
		placeBlockAtCurrentPosition(worldObj, Blocks.cobblestone, 0, 3, 5, 9, boundingbox);
		placeBlockAtCurrentPosition(worldObj, Blocks.cobblestone, 0, 3, 6, 1, boundingbox);
		placeBlockAtCurrentPosition(worldObj, Blocks.cobblestone, 0, 3, 6, 2, boundingbox);
		placeBlockAtCurrentPosition(worldObj, Blocks.cobblestone, 0, 3, 6, 3, boundingbox);
		placeBlockAtCurrentPosition(worldObj, Blocks.cobblestone, 0, 3, 6, 4, boundingbox);
		placeBlockAtCurrentPosition(worldObj, Blocks.cobblestone, 0, 3, 6, 5, boundingbox);
		placeBlockAtCurrentPosition(worldObj, Blocks.cobblestone, 0, 3, 6, 6, boundingbox);
		placeBlockAtCurrentPosition(worldObj, Blocks.cobblestone, 0, 3, 6, 7, boundingbox);
		placeBlockAtCurrentPosition(worldObj, Blocks.cobblestone, 0, 3, 6, 8, boundingbox);
		placeBlockAtCurrentPosition(worldObj, Blocks.cobblestone, 0, 3, 6, 9, boundingbox);
		placeBlockAtCurrentPosition(worldObj, Blocks.cobblestone, 0, 3, 7, 1, boundingbox);
		placeBlockAtCurrentPosition(worldObj, Blocks.cobblestone, 0, 3, 7, 2, boundingbox);
		placeBlockAtCurrentPosition(worldObj, Blocks.cobblestone, 0, 3, 7, 3, boundingbox);
		placeBlockAtCurrentPosition(worldObj, Blocks.cobblestone, 0, 3, 7, 4, boundingbox);
		placeBlockAtCurrentPosition(worldObj, Blocks.cobblestone, 0, 3, 7, 5, boundingbox);
		placeBlockAtCurrentPosition(worldObj, Blocks.cobblestone, 0, 3, 7, 6, boundingbox);
		placeBlockAtCurrentPosition(worldObj, Blocks.cobblestone, 0, 3, 7, 7, boundingbox);
		placeBlockAtCurrentPosition(worldObj, Blocks.cobblestone, 0, 3, 7, 8, boundingbox);
		placeBlockAtCurrentPosition(worldObj, Blocks.cobblestone, 0, 3, 7, 9, boundingbox);
		placeBlockAtCurrentPosition(worldObj, Blocks.cobblestone, 0, 4, 0, 1, boundingbox);
		placeBlockAtCurrentPosition(worldObj, Blocks.cobblestone, 0, 4, 0, 2, boundingbox);
		placeBlockAtCurrentPosition(worldObj, Blocks.cobblestone, 0, 4, 0, 3, boundingbox);
		placeBlockAtCurrentPosition(worldObj, Blocks.cobblestone, 0, 4, 0, 4, boundingbox);
		placeBlockAtCurrentPosition(worldObj, Blocks.cobblestone, 0, 4, 0, 5, boundingbox);
		placeBlockAtCurrentPosition(worldObj, Blocks.cobblestone, 0, 4, 0, 6, boundingbox);
		placeBlockAtCurrentPosition(worldObj, Blocks.cobblestone, 0, 4, 0, 7, boundingbox);
		placeBlockAtCurrentPosition(worldObj, Blocks.cobblestone, 0, 4, 0, 8, boundingbox);
		placeBlockAtCurrentPosition(worldObj, Blocks.cobblestone, 0, 4, 0, 9, boundingbox);
		placeBlockAtCurrentPosition(worldObj, Blocks.cobblestone, 0, 4, 1, 1, boundingbox);
		placeBlockAtCurrentPosition(worldObj, Blocks.cobblestone, 0, 4, 1, 9, boundingbox);
		placeBlockAtCurrentPosition(worldObj, Blocks.cobblestone, 0, 4, 2, 1, boundingbox);
		placeBlockAtCurrentPosition(worldObj, Blocks.cobblestone, 0, 4, 2, 9, boundingbox);
		placeBlockAtCurrentPosition(worldObj, Blocks.cobblestone, 0, 4, 3, 1, boundingbox);
		placeBlockAtCurrentPosition(worldObj, Blocks.cobblestone, 0, 4, 3, 9, boundingbox);
		placeBlockAtCurrentPosition(worldObj, Blocks.cobblestone, 0, 4, 4, 1, boundingbox);
		placeBlockAtCurrentPosition(worldObj, Blocks.cobblestone, 0, 4, 4, 9, boundingbox);
		placeBlockAtCurrentPosition(worldObj, Blocks.cobblestone, 0, 4, 5, 1, boundingbox);
		placeBlockAtCurrentPosition(worldObj, Blocks.cobblestone, 0, 4, 5, 9, boundingbox);
		placeBlockAtCurrentPosition(worldObj, Blocks.cobblestone, 0, 4, 6, 1, boundingbox);
		placeBlockAtCurrentPosition(worldObj, Blocks.cobblestone, 0, 4, 6, 9, boundingbox);
		placeBlockAtCurrentPosition(worldObj, Blocks.cobblestone, 0, 4, 7, 1, boundingbox);
		placeBlockAtCurrentPosition(worldObj, Blocks.cobblestone, 0, 4, 7, 2, boundingbox);
		placeBlockAtCurrentPosition(worldObj, Blocks.cobblestone, 0, 4, 7, 3, boundingbox);
		placeBlockAtCurrentPosition(worldObj, Blocks.cobblestone, 0, 4, 7, 4, boundingbox);
		placeBlockAtCurrentPosition(worldObj, Blocks.cobblestone, 0, 4, 7, 5, boundingbox);
		placeBlockAtCurrentPosition(worldObj, Blocks.cobblestone, 0, 4, 7, 6, boundingbox);
		placeBlockAtCurrentPosition(worldObj, Blocks.cobblestone, 0, 4, 7, 7, boundingbox);
		placeBlockAtCurrentPosition(worldObj, Blocks.cobblestone, 0, 4, 7, 8, boundingbox);
		placeBlockAtCurrentPosition(worldObj, Blocks.cobblestone, 0, 4, 7, 9, boundingbox);
		placeBlockAtCurrentPosition(worldObj, Blocks.cobblestone, 0, 4, 8, 4, boundingbox);
		placeBlockAtCurrentPosition(worldObj, Blocks.cobblestone, 0, 4, 8, 5, boundingbox);
		placeBlockAtCurrentPosition(worldObj, Blocks.cobblestone, 0, 4, 8, 6, boundingbox);
		placeBlockAtCurrentPosition(worldObj, Blocks.cobblestone, 0, 5, 0, 1, boundingbox);
		placeBlockAtCurrentPosition(worldObj, Blocks.cobblestone, 0, 5, 0, 2, boundingbox);
		placeBlockAtCurrentPosition(worldObj, Blocks.cobblestone, 0, 5, 0, 3, boundingbox);
		placeBlockAtCurrentPosition(worldObj, Blocks.cobblestone, 0, 5, 0, 4, boundingbox);
		placeBlockAtCurrentPosition(worldObj, Blocks.cobblestone, 0, 5, 0, 5, boundingbox);
		placeBlockAtCurrentPosition(worldObj, Blocks.cobblestone, 0, 5, 0, 6, boundingbox);
		placeBlockAtCurrentPosition(worldObj, Blocks.cobblestone, 0, 5, 0, 7, boundingbox);
		placeBlockAtCurrentPosition(worldObj, Blocks.cobblestone, 0, 5, 0, 8, boundingbox);
		placeBlockAtCurrentPosition(worldObj, Blocks.cobblestone, 0, 5, 0, 9, boundingbox);
		placeBlockAtCurrentPosition(worldObj, Blocks.cobblestone, 0, 5, 1, 1, boundingbox);
		placeBlockAtCurrentPosition(worldObj, Blocks.cobblestone, 0, 5, 1, 9, boundingbox);
		placeBlockAtCurrentPosition(worldObj, Blocks.cobblestone, 0, 5, 2, 1, boundingbox);
		placeBlockAtCurrentPosition(worldObj, Blocks.cobblestone, 0, 5, 2, 9, boundingbox);
		placeBlockAtCurrentPosition(worldObj, Blocks.cobblestone, 0, 5, 3, 1, boundingbox);
		placeBlockAtCurrentPosition(worldObj, Blocks.cobblestone, 0, 5, 3, 9, boundingbox);
		placeBlockAtCurrentPosition(worldObj, Blocks.cobblestone, 0, 5, 4, 1, boundingbox);
		placeBlockAtCurrentPosition(worldObj, Blocks.cobblestone, 0, 5, 4, 9, boundingbox);
		placeBlockAtCurrentPosition(worldObj, Blocks.cobblestone, 0, 5, 5, 1, boundingbox);
		placeBlockAtCurrentPosition(worldObj, Blocks.cobblestone, 0, 5, 5, 9, boundingbox);
		placeBlockAtCurrentPosition(worldObj, Blocks.cobblestone, 0, 5, 6, 1, boundingbox);
		placeBlockAtCurrentPosition(worldObj, Blocks.cobblestone, 0, 5, 6, 9, boundingbox);
		placeBlockAtCurrentPosition(worldObj, Blocks.cobblestone, 0, 5, 7, 1, boundingbox);
		placeBlockAtCurrentPosition(worldObj, Blocks.cobblestone, 0, 5, 7, 2, boundingbox);
		placeBlockAtCurrentPosition(worldObj, Blocks.cobblestone, 0, 5, 7, 3, boundingbox);
		placeBlockAtCurrentPosition(worldObj, Blocks.cobblestone, 0, 5, 7, 4, boundingbox);
		placeBlockAtCurrentPosition(worldObj, Blocks.cobblestone, 0, 5, 7, 5, boundingbox);
		placeBlockAtCurrentPosition(worldObj, Blocks.cobblestone, 0, 5, 7, 6, boundingbox);
		placeBlockAtCurrentPosition(worldObj, Blocks.cobblestone, 0, 5, 7, 7, boundingbox);
		placeBlockAtCurrentPosition(worldObj, Blocks.cobblestone, 0, 5, 7, 8, boundingbox);
		placeBlockAtCurrentPosition(worldObj, Blocks.cobblestone, 0, 5, 7, 9, boundingbox);
		placeBlockAtCurrentPosition(worldObj, Blocks.cobblestone, 0, 5, 8, 4, boundingbox);
		placeBlockAtCurrentPosition(worldObj, Blocks.cobblestone, 0, 5, 8, 5, boundingbox);
		placeBlockAtCurrentPosition(worldObj, Blocks.cobblestone, 0, 5, 8, 6, boundingbox);
		placeBlockAtCurrentPosition(worldObj, Blocks.cobblestone, 0, 5, 9, 5, boundingbox);
		placeBlockAtCurrentPosition(worldObj, Blocks.cobblestone, 0, 6, 0, 1, boundingbox);
		placeBlockAtCurrentPosition(worldObj, Blocks.cobblestone, 0, 6, 0, 2, boundingbox);
		placeBlockAtCurrentPosition(worldObj, Blocks.cobblestone, 0, 6, 0, 3, boundingbox);
		placeBlockAtCurrentPosition(worldObj, Blocks.cobblestone, 0, 6, 0, 4, boundingbox);
		placeBlockAtCurrentPosition(worldObj, Blocks.cobblestone, 0, 6, 0, 5, boundingbox);
		placeBlockAtCurrentPosition(worldObj, Blocks.cobblestone, 0, 6, 0, 6, boundingbox);
		placeBlockAtCurrentPosition(worldObj, Blocks.cobblestone, 0, 6, 0, 7, boundingbox);
		placeBlockAtCurrentPosition(worldObj, Blocks.cobblestone, 0, 6, 0, 8, boundingbox);
		placeBlockAtCurrentPosition(worldObj, Blocks.cobblestone, 0, 6, 0, 9, boundingbox);
		placeBlockAtCurrentPosition(worldObj, Blocks.cobblestone, 0, 6, 1, 1, boundingbox);
		placeBlockAtCurrentPosition(worldObj, Blocks.cobblestone, 0, 6, 1, 9, boundingbox);
		placeBlockAtCurrentPosition(worldObj, Blocks.cobblestone, 0, 6, 2, 1, boundingbox);
		placeBlockAtCurrentPosition(worldObj, Blocks.cobblestone, 0, 6, 2, 9, boundingbox);
		placeBlockAtCurrentPosition(worldObj, Blocks.cobblestone, 0, 6, 3, 1, boundingbox);
		placeBlockAtCurrentPosition(worldObj, Blocks.cobblestone, 0, 6, 3, 9, boundingbox);
		placeBlockAtCurrentPosition(worldObj, Blocks.cobblestone, 0, 6, 4, 1, boundingbox);
		placeBlockAtCurrentPosition(worldObj, Blocks.cobblestone, 0, 6, 4, 9, boundingbox);
		placeBlockAtCurrentPosition(worldObj, Blocks.cobblestone, 0, 6, 5, 1, boundingbox);
		placeBlockAtCurrentPosition(worldObj, Blocks.cobblestone, 0, 6, 5, 9, boundingbox);
		placeBlockAtCurrentPosition(worldObj, Blocks.cobblestone, 0, 6, 6, 1, boundingbox);
		placeBlockAtCurrentPosition(worldObj, Blocks.cobblestone, 0, 6, 6, 9, boundingbox);
		placeBlockAtCurrentPosition(worldObj, Blocks.cobblestone, 0, 6, 7, 1, boundingbox);
		placeBlockAtCurrentPosition(worldObj, Blocks.cobblestone, 0, 6, 7, 2, boundingbox);
		placeBlockAtCurrentPosition(worldObj, Blocks.cobblestone, 0, 6, 7, 3, boundingbox);
		placeBlockAtCurrentPosition(worldObj, Blocks.cobblestone, 0, 6, 7, 4, boundingbox);
		placeBlockAtCurrentPosition(worldObj, Blocks.cobblestone, 0, 6, 7, 5, boundingbox);
		placeBlockAtCurrentPosition(worldObj, Blocks.cobblestone, 0, 6, 7, 6, boundingbox);
		placeBlockAtCurrentPosition(worldObj, Blocks.cobblestone, 0, 6, 7, 7, boundingbox);
		placeBlockAtCurrentPosition(worldObj, Blocks.cobblestone, 0, 6, 7, 8, boundingbox);
		placeBlockAtCurrentPosition(worldObj, Blocks.cobblestone, 0, 6, 7, 9, boundingbox);
		placeBlockAtCurrentPosition(worldObj, Blocks.cobblestone, 0, 6, 8, 4, boundingbox);
		placeBlockAtCurrentPosition(worldObj, Blocks.cobblestone, 0, 6, 8, 5, boundingbox);
		placeBlockAtCurrentPosition(worldObj, Blocks.cobblestone, 0, 6, 8, 6, boundingbox);
		placeBlockAtCurrentPosition(worldObj, Blocks.cobblestone, 0, 6, 9, 5, boundingbox);
		placeBlockAtCurrentPosition(worldObj, Blocks.cobblestone, 0, 7, 0, 1, boundingbox);
		placeBlockAtCurrentPosition(worldObj, Blocks.cobblestone, 0, 7, 0, 2, boundingbox);
		placeBlockAtCurrentPosition(worldObj, Blocks.cobblestone, 0, 7, 0, 3, boundingbox);
		placeBlockAtCurrentPosition(worldObj, Blocks.cobblestone, 0, 7, 0, 4, boundingbox);
		placeBlockAtCurrentPosition(worldObj, Blocks.cobblestone, 0, 7, 0, 5, boundingbox);
		placeBlockAtCurrentPosition(worldObj, Blocks.cobblestone, 0, 7, 0, 6, boundingbox);
		placeBlockAtCurrentPosition(worldObj, Blocks.cobblestone, 0, 7, 0, 7, boundingbox);
		placeBlockAtCurrentPosition(worldObj, Blocks.cobblestone, 0, 7, 0, 8, boundingbox);
		placeBlockAtCurrentPosition(worldObj, Blocks.cobblestone, 0, 7, 0, 9, boundingbox);
		placeBlockAtCurrentPosition(worldObj, Blocks.cobblestone, 0, 7, 1, 1, boundingbox);
		placeBlockAtCurrentPosition(worldObj, Blocks.cobblestone, 0, 7, 1, 9, boundingbox);
		placeBlockAtCurrentPosition(worldObj, Blocks.cobblestone, 0, 7, 2, 1, boundingbox);
		placeBlockAtCurrentPosition(worldObj, Blocks.cobblestone, 0, 7, 2, 9, boundingbox);
		placeBlockAtCurrentPosition(worldObj, Blocks.cobblestone, 0, 7, 3, 1, boundingbox);
		placeBlockAtCurrentPosition(worldObj, Blocks.cobblestone, 0, 7, 3, 9, boundingbox);
		placeBlockAtCurrentPosition(worldObj, Blocks.cobblestone, 0, 7, 4, 1, boundingbox);
		placeBlockAtCurrentPosition(worldObj, Blocks.cobblestone, 0, 7, 4, 9, boundingbox);
		placeBlockAtCurrentPosition(worldObj, Blocks.cobblestone, 0, 7, 5, 1, boundingbox);
		placeBlockAtCurrentPosition(worldObj, Blocks.cobblestone, 0, 7, 5, 9, boundingbox);
		placeBlockAtCurrentPosition(worldObj, Blocks.cobblestone, 0, 7, 6, 1, boundingbox);
		placeBlockAtCurrentPosition(worldObj, Blocks.cobblestone, 0, 7, 7, 1, boundingbox);
		placeBlockAtCurrentPosition(worldObj, Blocks.cobblestone, 0, 7, 7, 2, boundingbox);
		placeBlockAtCurrentPosition(worldObj, Blocks.cobblestone, 0, 7, 7, 3, boundingbox);
		placeBlockAtCurrentPosition(worldObj, Blocks.cobblestone, 0, 7, 7, 4, boundingbox);
		placeBlockAtCurrentPosition(worldObj, Blocks.cobblestone, 0, 7, 7, 5, boundingbox);
		placeBlockAtCurrentPosition(worldObj, Blocks.cobblestone, 0, 7, 7, 6, boundingbox);
		placeBlockAtCurrentPosition(worldObj, Blocks.cobblestone, 0, 7, 7, 7, boundingbox);
		placeBlockAtCurrentPosition(worldObj, Blocks.cobblestone, 0, 7, 7, 8, boundingbox);
		placeBlockAtCurrentPosition(worldObj, Blocks.cobblestone, 0, 7, 7, 9, boundingbox);
		placeBlockAtCurrentPosition(worldObj, Blocks.cobblestone, 0, 7, 8, 4, boundingbox);
		placeBlockAtCurrentPosition(worldObj, Blocks.cobblestone, 0, 7, 8, 5, boundingbox);
		placeBlockAtCurrentPosition(worldObj, Blocks.cobblestone, 0, 7, 8, 6, boundingbox);
		placeBlockAtCurrentPosition(worldObj, Blocks.cobblestone, 0, 7, 9, 5, boundingbox);
		placeBlockAtCurrentPosition(worldObj, Blocks.cobblestone, 0, 8, 0, 1, boundingbox);
		placeBlockAtCurrentPosition(worldObj, Blocks.cobblestone, 0, 8, 0, 2, boundingbox);
		placeBlockAtCurrentPosition(worldObj, Blocks.cobblestone, 0, 8, 0, 3, boundingbox);
		placeBlockAtCurrentPosition(worldObj, Blocks.cobblestone, 0, 8, 0, 4, boundingbox);
		placeBlockAtCurrentPosition(worldObj, Blocks.cobblestone, 0, 8, 0, 5, boundingbox);
		placeBlockAtCurrentPosition(worldObj, Blocks.cobblestone, 0, 8, 0, 6, boundingbox);
		placeBlockAtCurrentPosition(worldObj, Blocks.cobblestone, 0, 8, 0, 7, boundingbox);
		placeBlockAtCurrentPosition(worldObj, Blocks.cobblestone, 0, 8, 0, 8, boundingbox);
		placeBlockAtCurrentPosition(worldObj, Blocks.cobblestone, 0, 8, 0, 9, boundingbox);
		placeBlockAtCurrentPosition(worldObj, Blocks.cobblestone, 0, 8, 1, 1, boundingbox);
		placeBlockAtCurrentPosition(worldObj, Blocks.cobblestone, 0, 8, 1, 9, boundingbox);
		placeBlockAtCurrentPosition(worldObj, Blocks.cobblestone, 0, 8, 2, 1, boundingbox);
		placeBlockAtCurrentPosition(worldObj, Blocks.cobblestone, 0, 8, 2, 9, boundingbox);
		placeBlockAtCurrentPosition(worldObj, Blocks.cobblestone, 0, 8, 3, 1, boundingbox);
		placeBlockAtCurrentPosition(worldObj, Blocks.cobblestone, 0, 8, 3, 9, boundingbox);
		placeBlockAtCurrentPosition(worldObj, Blocks.cobblestone, 0, 8, 4, 1, boundingbox);
		placeBlockAtCurrentPosition(worldObj, Blocks.cobblestone, 0, 8, 4, 9, boundingbox);
		placeBlockAtCurrentPosition(worldObj, Blocks.cobblestone, 0, 8, 5, 1, boundingbox);
		placeBlockAtCurrentPosition(worldObj, Blocks.cobblestone, 0, 8, 5, 9, boundingbox);
		placeBlockAtCurrentPosition(worldObj, Blocks.cobblestone, 0, 8, 6, 1, boundingbox);
		placeBlockAtCurrentPosition(worldObj, Blocks.cobblestone, 0, 8, 6, 9, boundingbox);
		placeBlockAtCurrentPosition(worldObj, Blocks.cobblestone, 0, 8, 7, 1, boundingbox);
		placeBlockAtCurrentPosition(worldObj, Blocks.cobblestone, 0, 8, 7, 2, boundingbox);
		placeBlockAtCurrentPosition(worldObj, Blocks.cobblestone, 0, 8, 7, 3, boundingbox);
		placeBlockAtCurrentPosition(worldObj, Blocks.cobblestone, 0, 8, 7, 4, boundingbox);
		placeBlockAtCurrentPosition(worldObj, Blocks.cobblestone, 0, 8, 7, 5, boundingbox);
		placeBlockAtCurrentPosition(worldObj, Blocks.cobblestone, 0, 8, 7, 6, boundingbox);
		placeBlockAtCurrentPosition(worldObj, Blocks.cobblestone, 0, 8, 7, 7, boundingbox);
		placeBlockAtCurrentPosition(worldObj, Blocks.cobblestone, 0, 8, 7, 8, boundingbox);
		placeBlockAtCurrentPosition(worldObj, Blocks.cobblestone, 0, 8, 7, 9, boundingbox);
		placeBlockAtCurrentPosition(worldObj, Blocks.cobblestone, 0, 8, 8, 4, boundingbox);
		placeBlockAtCurrentPosition(worldObj, Blocks.cobblestone, 0, 8, 8, 5, boundingbox);
		placeBlockAtCurrentPosition(worldObj, Blocks.cobblestone, 0, 8, 8, 6, boundingbox);
		placeBlockAtCurrentPosition(worldObj, Blocks.cobblestone, 0, 9, 0, 1, boundingbox);
		placeBlockAtCurrentPosition(worldObj, Blocks.cobblestone, 0, 9, 0, 2, boundingbox);
		placeBlockAtCurrentPosition(worldObj, Blocks.cobblestone, 0, 9, 0, 3, boundingbox);
		placeBlockAtCurrentPosition(worldObj, Blocks.cobblestone, 0, 9, 0, 4, boundingbox);
		placeBlockAtCurrentPosition(worldObj, Blocks.cobblestone, 0, 9, 0, 5, boundingbox);
		placeBlockAtCurrentPosition(worldObj, Blocks.cobblestone, 0, 9, 0, 6, boundingbox);
		placeBlockAtCurrentPosition(worldObj, Blocks.cobblestone, 0, 9, 0, 7, boundingbox);
		placeBlockAtCurrentPosition(worldObj, Blocks.cobblestone, 0, 9, 0, 8, boundingbox);
		placeBlockAtCurrentPosition(worldObj, Blocks.cobblestone, 0, 9, 0, 9, boundingbox);
		placeBlockAtCurrentPosition(worldObj, Blocks.cobblestone, 0, 9, 1, 1, boundingbox);
		placeBlockAtCurrentPosition(worldObj, Blocks.cobblestone, 0, 9, 1, 2, boundingbox);
		placeBlockAtCurrentPosition(worldObj, Blocks.cobblestone, 0, 9, 1, 3, boundingbox);
		placeBlockAtCurrentPosition(worldObj, Blocks.cobblestone, 0, 9, 1, 4, boundingbox);
		placeBlockAtCurrentPosition(worldObj, Blocks.cobblestone, 0, 9, 1, 5, boundingbox);
		placeBlockAtCurrentPosition(worldObj, Blocks.cobblestone, 0, 9, 1, 6, boundingbox);
		placeBlockAtCurrentPosition(worldObj, Blocks.cobblestone, 0, 9, 1, 7, boundingbox);
		placeBlockAtCurrentPosition(worldObj, Blocks.cobblestone, 0, 9, 1, 8, boundingbox);
		placeBlockAtCurrentPosition(worldObj, Blocks.cobblestone, 0, 9, 1, 9, boundingbox);
		placeBlockAtCurrentPosition(worldObj, Blocks.cobblestone, 0, 9, 2, 1, boundingbox);
		placeBlockAtCurrentPosition(worldObj, Blocks.cobblestone, 0, 9, 2, 2, boundingbox);
		placeBlockAtCurrentPosition(worldObj, Blocks.cobblestone, 0, 9, 2, 3, boundingbox);
		placeBlockAtCurrentPosition(worldObj, Blocks.cobblestone, 0, 9, 2, 4, boundingbox);
		placeBlockAtCurrentPosition(worldObj, Blocks.cobblestone, 0, 9, 2, 5, boundingbox);
		placeBlockAtCurrentPosition(worldObj, Blocks.cobblestone, 0, 9, 2, 6, boundingbox);
		placeBlockAtCurrentPosition(worldObj, Blocks.cobblestone, 0, 9, 2, 7, boundingbox);
		placeBlockAtCurrentPosition(worldObj, Blocks.cobblestone, 0, 9, 2, 8, boundingbox);
		placeBlockAtCurrentPosition(worldObj, Blocks.cobblestone, 0, 9, 2, 9, boundingbox);
		placeBlockAtCurrentPosition(worldObj, Blocks.cobblestone, 0, 9, 3, 1, boundingbox);
		placeBlockAtCurrentPosition(worldObj, Blocks.cobblestone, 0, 9, 3, 2, boundingbox);
		placeBlockAtCurrentPosition(worldObj, Blocks.cobblestone, 0, 9, 3, 3, boundingbox);
		placeBlockAtCurrentPosition(worldObj, Blocks.cobblestone, 0, 9, 3, 4, boundingbox);
		placeBlockAtCurrentPosition(worldObj, Blocks.cobblestone, 0, 9, 3, 5, boundingbox);
		placeBlockAtCurrentPosition(worldObj, Blocks.cobblestone, 0, 9, 3, 6, boundingbox);
		placeBlockAtCurrentPosition(worldObj, Blocks.cobblestone, 0, 9, 3, 7, boundingbox);
		placeBlockAtCurrentPosition(worldObj, Blocks.cobblestone, 0, 9, 3, 8, boundingbox);
		placeBlockAtCurrentPosition(worldObj, Blocks.cobblestone, 0, 9, 3, 9, boundingbox);
		placeBlockAtCurrentPosition(worldObj, Blocks.cobblestone, 0, 9, 4, 1, boundingbox);
		placeBlockAtCurrentPosition(worldObj, Blocks.cobblestone, 0, 9, 4, 2, boundingbox);
		placeBlockAtCurrentPosition(worldObj, Blocks.cobblestone, 0, 9, 4, 3, boundingbox);
		placeBlockAtCurrentPosition(worldObj, Blocks.cobblestone, 0, 9, 4, 4, boundingbox);
		placeBlockAtCurrentPosition(worldObj, Blocks.cobblestone, 0, 9, 4, 5, boundingbox);
		placeBlockAtCurrentPosition(worldObj, Blocks.cobblestone, 0, 9, 4, 6, boundingbox);
		placeBlockAtCurrentPosition(worldObj, Blocks.cobblestone, 0, 9, 4, 7, boundingbox);
		placeBlockAtCurrentPosition(worldObj, Blocks.cobblestone, 0, 9, 4, 8, boundingbox);
		placeBlockAtCurrentPosition(worldObj, Blocks.cobblestone, 0, 9, 4, 9, boundingbox);
		placeBlockAtCurrentPosition(worldObj, Blocks.cobblestone, 0, 9, 5, 1, boundingbox);
		placeBlockAtCurrentPosition(worldObj, Blocks.cobblestone, 0, 9, 5, 2, boundingbox);
		placeBlockAtCurrentPosition(worldObj, Blocks.cobblestone, 0, 9, 5, 3, boundingbox);
		placeBlockAtCurrentPosition(worldObj, Blocks.cobblestone, 0, 9, 5, 4, boundingbox);
		placeBlockAtCurrentPosition(worldObj, Blocks.cobblestone, 0, 9, 5, 5, boundingbox);
		placeBlockAtCurrentPosition(worldObj, Blocks.cobblestone, 0, 9, 5, 6, boundingbox);
		placeBlockAtCurrentPosition(worldObj, Blocks.cobblestone, 0, 9, 5, 7, boundingbox);
		placeBlockAtCurrentPosition(worldObj, Blocks.cobblestone, 0, 9, 5, 8, boundingbox);
		placeBlockAtCurrentPosition(worldObj, Blocks.cobblestone, 0, 9, 5, 9, boundingbox);
		placeBlockAtCurrentPosition(worldObj, Blocks.cobblestone, 0, 9, 6, 1, boundingbox);
		placeBlockAtCurrentPosition(worldObj, Blocks.cobblestone, 0, 9, 6, 2, boundingbox);
		placeBlockAtCurrentPosition(worldObj, Blocks.cobblestone, 0, 9, 6, 3, boundingbox);
		placeBlockAtCurrentPosition(worldObj, Blocks.cobblestone, 0, 9, 6, 4, boundingbox);
		placeBlockAtCurrentPosition(worldObj, Blocks.cobblestone, 0, 9, 6, 5, boundingbox);
		placeBlockAtCurrentPosition(worldObj, Blocks.cobblestone, 0, 9, 6, 6, boundingbox);
		placeBlockAtCurrentPosition(worldObj, Blocks.cobblestone, 0, 9, 6, 7, boundingbox);
		placeBlockAtCurrentPosition(worldObj, Blocks.cobblestone, 0, 9, 6, 8, boundingbox);
		placeBlockAtCurrentPosition(worldObj, Blocks.cobblestone, 0, 9, 6, 9, boundingbox);
		placeBlockAtCurrentPosition(worldObj, Blocks.cobblestone, 0, 9, 7, 1, boundingbox);
		placeBlockAtCurrentPosition(worldObj, Blocks.cobblestone, 0, 9, 7, 2, boundingbox);
		placeBlockAtCurrentPosition(worldObj, Blocks.cobblestone, 0, 9, 7, 3, boundingbox);
		placeBlockAtCurrentPosition(worldObj, Blocks.cobblestone, 0, 9, 7, 4, boundingbox);
		placeBlockAtCurrentPosition(worldObj, Blocks.cobblestone, 0, 9, 7, 5, boundingbox);
		placeBlockAtCurrentPosition(worldObj, Blocks.cobblestone, 0, 9, 7, 6, boundingbox);
		placeBlockAtCurrentPosition(worldObj, Blocks.cobblestone, 0, 9, 7, 7, boundingbox);
		placeBlockAtCurrentPosition(worldObj, Blocks.cobblestone, 0, 9, 7, 8, boundingbox);
		placeBlockAtCurrentPosition(worldObj, Blocks.cobblestone, 0, 9, 7, 9, boundingbox);
		placeBlockAtCurrentPosition(worldObj, Blocks.cobblestone, 0, 7, 6, 9, boundingbox);
		placeBlockAtCurrentPosition(worldObj, Blocks.planks, 0, 4, 1, 8, boundingbox);
		placeBlockAtCurrentPosition(worldObj, Blocks.planks, 0, 4, 2, 2, boundingbox);
		placeBlockAtCurrentPosition(worldObj, Blocks.planks, 0, 4, 2, 8, boundingbox);
		placeBlockAtCurrentPosition(worldObj, Blocks.planks, 0, 4, 3, 2, boundingbox);
		placeBlockAtCurrentPosition(worldObj, Blocks.planks, 0, 4, 3, 8, boundingbox);
		placeBlockAtCurrentPosition(worldObj, Blocks.planks, 0, 4, 4, 2, boundingbox);
		placeBlockAtCurrentPosition(worldObj, Blocks.planks, 0, 4, 4, 8, boundingbox);
		placeBlockAtCurrentPosition(worldObj, Blocks.planks, 0, 8, 1, 2, boundingbox);
		placeBlockAtCurrentPosition(worldObj, Blocks.planks, 0, 8, 1, 8, boundingbox);
		placeBlockAtCurrentPosition(worldObj, Blocks.planks, 0, 8, 2, 2, boundingbox);
		placeBlockAtCurrentPosition(worldObj, Blocks.planks, 0, 8, 2, 8, boundingbox);
		placeBlockAtCurrentPosition(worldObj, Blocks.planks, 0, 8, 3, 2, boundingbox);
		placeBlockAtCurrentPosition(worldObj, Blocks.planks, 0, 8, 3, 8, boundingbox);
		placeBlockAtCurrentPosition(worldObj, Blocks.planks, 0, 8, 4, 2, boundingbox);
		placeBlockAtCurrentPosition(worldObj, Blocks.planks, 0, 8, 4, 8, boundingbox);
		placeBlockAtCurrentPosition(worldObj, Blocks.stone_stairs, var0, 0, 0, 4, boundingbox);
		placeBlockAtCurrentPosition(worldObj, Blocks.stone_stairs, var0, 0, 0, 5, boundingbox);
		placeBlockAtCurrentPosition(worldObj, Blocks.stone_stairs, var0, 0, 0, 6, boundingbox);
		placeBlockAtCurrentPosition(worldObj, Blocks.stone_stairs, var0, 2, 0, 0, boundingbox);
		placeBlockAtCurrentPosition(worldObj, Blocks.stone_stairs, var0, 2, 0, 1, boundingbox);
		placeBlockAtCurrentPosition(worldObj, Blocks.stone_stairs, var0, 2, 0, 2, boundingbox);
		placeBlockAtCurrentPosition(worldObj, Blocks.stone_stairs, var0, 2, 0, 3, boundingbox);
		placeBlockAtCurrentPosition(worldObj, Blocks.stone_stairs, var0, 2, 0, 8, boundingbox);
		placeBlockAtCurrentPosition(worldObj, Blocks.stone_stairs, var0, 2, 0, 9, boundingbox);
		placeBlockAtCurrentPosition(worldObj, Blocks.stone_stairs, var0, 3, 8, 4, boundingbox);
		placeBlockAtCurrentPosition(worldObj, Blocks.stone_stairs, var0, 3, 8, 5, boundingbox);
		placeBlockAtCurrentPosition(worldObj, Blocks.stone_stairs, var0, 3, 8, 6, boundingbox);
		placeBlockAtCurrentPosition(worldObj, Blocks.stone_stairs, var0, 4, 9, 4, boundingbox);
		placeBlockAtCurrentPosition(worldObj, Blocks.stone_stairs, var0, 4, 9, 5, boundingbox);
		placeBlockAtCurrentPosition(worldObj, Blocks.stone_stairs, var0, 4, 9, 6, boundingbox);
		placeBlockAtCurrentPosition(worldObj, Blocks.stone_stairs, var1, 8, 9, 4, boundingbox);
		placeBlockAtCurrentPosition(worldObj, Blocks.stone_stairs, var1, 8, 9, 5, boundingbox);
		placeBlockAtCurrentPosition(worldObj, Blocks.stone_stairs, var1, 9, 8, 4, boundingbox);
		placeBlockAtCurrentPosition(worldObj, Blocks.stone_stairs, var1, 9, 8, 5, boundingbox);
		placeBlockAtCurrentPosition(worldObj, Blocks.stone_stairs, var1, 9, 8, 6, boundingbox);
		placeBlockAtCurrentPosition(worldObj, Blocks.stone_stairs, var1, 9, 8, 7, boundingbox);
		placeBlockAtCurrentPosition(worldObj, Blocks.stone_stairs, var1, 10, 0, 1, boundingbox);
		placeBlockAtCurrentPosition(worldObj, Blocks.stone_stairs, var1, 10, 0, 2, boundingbox);
		placeBlockAtCurrentPosition(worldObj, Blocks.stone_stairs, var1, 10, 0, 3, boundingbox);
		placeBlockAtCurrentPosition(worldObj, Blocks.stone_stairs, var1, 10, 0, 4, boundingbox);
		placeBlockAtCurrentPosition(worldObj, Blocks.stone_stairs, var1, 10, 0, 5, boundingbox);
		placeBlockAtCurrentPosition(worldObj, Blocks.stone_stairs, var1, 10, 0, 6, boundingbox);
		placeBlockAtCurrentPosition(worldObj, Blocks.stone_stairs, var1, 10, 0, 7, boundingbox);
		placeBlockAtCurrentPosition(worldObj, Blocks.stone_stairs, var1, 10, 0, 8, boundingbox);
		placeBlockAtCurrentPosition(worldObj, Blocks.stone_stairs, var1, 10, 0, 9, boundingbox);
		placeBlockAtCurrentPosition(worldObj, Blocks.stone_stairs, var1, 10, 0, 10, boundingbox);
		placeBlockAtCurrentPosition(worldObj, Blocks.stone_stairs, var2, 0, 0, 3, boundingbox);
		placeBlockAtCurrentPosition(worldObj, Blocks.stone_stairs, var2, 1, 0, 3, boundingbox);
		placeBlockAtCurrentPosition(worldObj, Blocks.stone_stairs, var2, 1, 4, 3, boundingbox);
		placeBlockAtCurrentPosition(worldObj, Blocks.stone_stairs, var2, 1, 5, 4, boundingbox);
		placeBlockAtCurrentPosition(worldObj, Blocks.stone_stairs, var2, 2, 4, 3, boundingbox);
		placeBlockAtCurrentPosition(worldObj, Blocks.stone_stairs, var2, 2, 5, 4, boundingbox);
		placeBlockAtCurrentPosition(worldObj, Blocks.stone_stairs, var2, 3, 0, 0, boundingbox);
		placeBlockAtCurrentPosition(worldObj, Blocks.stone_stairs, var2, 3, 8, 3, boundingbox);
		placeBlockAtCurrentPosition(worldObj, Blocks.stone_stairs, var2, 4, 0, 0, boundingbox);
		placeBlockAtCurrentPosition(worldObj, Blocks.stone_stairs, var2, 4, 8, 3, boundingbox);
		placeBlockAtCurrentPosition(worldObj, Blocks.stone_stairs, var2, 5, 0, 0, boundingbox);
		placeBlockAtCurrentPosition(worldObj, Blocks.stone_stairs, var2, 5, 8, 3, boundingbox);
		placeBlockAtCurrentPosition(worldObj, Blocks.stone_stairs, var2, 5, 9, 4, boundingbox);
		placeBlockAtCurrentPosition(worldObj, Blocks.stone_stairs, var2, 6, 0, 0, boundingbox);
		placeBlockAtCurrentPosition(worldObj, Blocks.stone_stairs, var2, 6, 8, 3, boundingbox);
		placeBlockAtCurrentPosition(worldObj, Blocks.stone_stairs, var2, 6, 9, 4, boundingbox);
		placeBlockAtCurrentPosition(worldObj, Blocks.stone_stairs, var2, 7, 0, 0, boundingbox);
		placeBlockAtCurrentPosition(worldObj, Blocks.stone_stairs, var2, 7, 8, 3, boundingbox);
		placeBlockAtCurrentPosition(worldObj, Blocks.stone_stairs, var2, 7, 9, 4, boundingbox);
		placeBlockAtCurrentPosition(worldObj, Blocks.stone_stairs, var2, 8, 0, 0, boundingbox);
		placeBlockAtCurrentPosition(worldObj, Blocks.stone_stairs, var2, 8, 8, 3, boundingbox);
		placeBlockAtCurrentPosition(worldObj, Blocks.stone_stairs, var2, 9, 0, 0, boundingbox);
		placeBlockAtCurrentPosition(worldObj, Blocks.stone_stairs, var2, 9, 8, 3, boundingbox);
		placeBlockAtCurrentPosition(worldObj, Blocks.stone_stairs, var2, 10, 0, 0, boundingbox);
		placeBlockAtCurrentPosition(worldObj, Blocks.stone_stairs, var3, 0, 0, 7, boundingbox);
		placeBlockAtCurrentPosition(worldObj, Blocks.stone_stairs, var3, 1, 0, 7, boundingbox);
		placeBlockAtCurrentPosition(worldObj, Blocks.stone_stairs, var3, 1, 4, 7, boundingbox);
		placeBlockAtCurrentPosition(worldObj, Blocks.stone_stairs, var3, 1, 5, 6, boundingbox);
		placeBlockAtCurrentPosition(worldObj, Blocks.stone_stairs, var3, 2, 0, 7, boundingbox);
		placeBlockAtCurrentPosition(worldObj, Blocks.stone_stairs, var3, 2, 0, 10, boundingbox);
		placeBlockAtCurrentPosition(worldObj, Blocks.stone_stairs, var3, 2, 4, 7, boundingbox);
		placeBlockAtCurrentPosition(worldObj, Blocks.stone_stairs, var3, 2, 5, 6, boundingbox);
		placeBlockAtCurrentPosition(worldObj, Blocks.stone_stairs, var3, 3, 0, 10, boundingbox);
		placeBlockAtCurrentPosition(worldObj, Blocks.stone_stairs, var3, 3, 8, 7, boundingbox);
		placeBlockAtCurrentPosition(worldObj, Blocks.stone_stairs, var3, 4, 0, 10, boundingbox);
		placeBlockAtCurrentPosition(worldObj, Blocks.stone_stairs, var3, 4, 8, 7, boundingbox);
		placeBlockAtCurrentPosition(worldObj, Blocks.stone_stairs, var3, 5, 0, 10, boundingbox);
		placeBlockAtCurrentPosition(worldObj, Blocks.stone_stairs, var3, 5, 8, 7, boundingbox);
		placeBlockAtCurrentPosition(worldObj, Blocks.stone_stairs, var3, 5, 9, 6, boundingbox);
		placeBlockAtCurrentPosition(worldObj, Blocks.stone_stairs, var3, 6, 0, 10, boundingbox);
		placeBlockAtCurrentPosition(worldObj, Blocks.stone_stairs, var3, 6, 8, 7, boundingbox);
		placeBlockAtCurrentPosition(worldObj, Blocks.stone_stairs, var3, 6, 9, 6, boundingbox);
		placeBlockAtCurrentPosition(worldObj, Blocks.stone_stairs, var3, 7, 0, 10, boundingbox);
		placeBlockAtCurrentPosition(worldObj, Blocks.stone_stairs, var3, 7, 8, 7, boundingbox);
		placeBlockAtCurrentPosition(worldObj, Blocks.stone_stairs, var3, 7, 9, 6, boundingbox);
		placeBlockAtCurrentPosition(worldObj, Blocks.stone_stairs, var3, 8, 0, 10, boundingbox);
		placeBlockAtCurrentPosition(worldObj, Blocks.stone_stairs, var3, 8, 8, 7, boundingbox);
		placeBlockAtCurrentPosition(worldObj, Blocks.stone_stairs, var3, 8, 9, 6, boundingbox);
		placeBlockAtCurrentPosition(worldObj, Blocks.stone_stairs, var3, 9, 0, 10, boundingbox);
		placeBlockAtCurrentPosition(worldObj, Blocks.stone_stairs, var4, 2, 7, 1, boundingbox);
		placeBlockAtCurrentPosition(worldObj, Blocks.stone_stairs, var4, 2, 7, 2, boundingbox);
		placeBlockAtCurrentPosition(worldObj, Blocks.stone_stairs, var4, 2, 7, 3, boundingbox);
		placeBlockAtCurrentPosition(worldObj, Blocks.stone_stairs, var4, 2, 7, 4, boundingbox);
		placeBlockAtCurrentPosition(worldObj, Blocks.stone_stairs, var4, 2, 7, 5, boundingbox);
		placeBlockAtCurrentPosition(worldObj, Blocks.stone_stairs, var4, 2, 7, 6, boundingbox);
		placeBlockAtCurrentPosition(worldObj, Blocks.stone_stairs, var4, 2, 7, 7, boundingbox);
		placeBlockAtCurrentPosition(worldObj, Blocks.stone_stairs, var4, 2, 7, 8, boundingbox);
		placeBlockAtCurrentPosition(worldObj, Blocks.stone_stairs, var4, 2, 7, 9, boundingbox);
		placeBlockAtCurrentPosition(worldObj, Blocks.stone_stairs, var4, 2, 7, 10, boundingbox);
		placeBlockAtCurrentPosition(worldObj, Blocks.stone_stairs, var5, 10, 7, 0, boundingbox);
		placeBlockAtCurrentPosition(worldObj, Blocks.stone_stairs, var5, 10, 7, 1, boundingbox);
		placeBlockAtCurrentPosition(worldObj, Blocks.stone_stairs, var5, 10, 7, 2, boundingbox);
		placeBlockAtCurrentPosition(worldObj, Blocks.stone_stairs, var5, 10, 7, 3, boundingbox);
		placeBlockAtCurrentPosition(worldObj, Blocks.stone_stairs, var5, 10, 7, 4, boundingbox);
		placeBlockAtCurrentPosition(worldObj, Blocks.stone_stairs, var5, 10, 7, 5, boundingbox);
		placeBlockAtCurrentPosition(worldObj, Blocks.stone_stairs, var5, 10, 7, 6, boundingbox);
		placeBlockAtCurrentPosition(worldObj, Blocks.stone_stairs, var5, 10, 7, 7, boundingbox);
		placeBlockAtCurrentPosition(worldObj, Blocks.stone_stairs, var5, 10, 7, 8, boundingbox);
		placeBlockAtCurrentPosition(worldObj, Blocks.stone_stairs, var5, 10, 7, 9, boundingbox);
		placeBlockAtCurrentPosition(worldObj, Blocks.stone_stairs, var6, 2, 7, 0, boundingbox);
		placeBlockAtCurrentPosition(worldObj, Blocks.stone_stairs, var6, 3, 7, 0, boundingbox);
		placeBlockAtCurrentPosition(worldObj, Blocks.stone_stairs, var6, 4, 7, 0, boundingbox);
		placeBlockAtCurrentPosition(worldObj, Blocks.stone_stairs, var6, 5, 7, 0, boundingbox);
		placeBlockAtCurrentPosition(worldObj, Blocks.stone_stairs, var6, 6, 7, 0, boundingbox);
		placeBlockAtCurrentPosition(worldObj, Blocks.stone_stairs, var6, 7, 7, 0, boundingbox);
		placeBlockAtCurrentPosition(worldObj, Blocks.stone_stairs, var6, 8, 7, 0, boundingbox);
		placeBlockAtCurrentPosition(worldObj, Blocks.stone_stairs, var6, 9, 7, 0, boundingbox);
		placeBlockAtCurrentPosition(worldObj, Blocks.stone_stairs, var7, 3, 7, 10, boundingbox);
		placeBlockAtCurrentPosition(worldObj, Blocks.stone_stairs, var7, 4, 7, 10, boundingbox);
		placeBlockAtCurrentPosition(worldObj, Blocks.stone_stairs, var7, 5, 7, 10, boundingbox);
		placeBlockAtCurrentPosition(worldObj, Blocks.stone_stairs, var7, 6, 7, 10, boundingbox);
		placeBlockAtCurrentPosition(worldObj, Blocks.stone_stairs, var7, 7, 7, 10, boundingbox);
		placeBlockAtCurrentPosition(worldObj, Blocks.stone_stairs, var7, 8, 7, 10, boundingbox);
		placeBlockAtCurrentPosition(worldObj, Blocks.stone_stairs, var7, 9, 7, 10, boundingbox);
		placeBlockAtCurrentPosition(worldObj, Blocks.stone_stairs, var7, 10, 7, 10, boundingbox);
		placeBlockAtCurrentPosition(worldObj, Blocks.stone_slab, 3, 1, 4, 4, boundingbox);
		placeBlockAtCurrentPosition(worldObj, Blocks.stone_slab, 3, 1, 4, 5, boundingbox);
		placeBlockAtCurrentPosition(worldObj, Blocks.stone_slab, 3, 1, 4, 6, boundingbox);
		placeBlockAtCurrentPosition(worldObj, Blocks.stone_slab, 11, 1, 5, 5, boundingbox);
		placeBlockAtCurrentPosition(worldObj, Blocks.stone_slab, 11, 3, 3, 5, boundingbox);
		placeBlockAtCurrentPosition(worldObj, Blocks.stone_slab, 3, 5, 10, 5, boundingbox);
		placeBlockAtCurrentPosition(worldObj, Blocks.stone_slab, 3, 6, 10, 5, boundingbox);
		placeBlockAtCurrentPosition(worldObj, Blocks.stone_slab, 3, 7, 10, 5, boundingbox);
		placeBlockAtCurrentPosition(worldObj, Blocks.web, 0, 4, 5, 2, boundingbox);
		placeBlockAtCurrentPosition(worldObj, Blocks.web, 0, 4, 6, 2, boundingbox);
		placeBlockAtCurrentPosition(worldObj, Blocks.web, 0, 4, 6, 3, boundingbox);
		placeBlockAtCurrentPosition(worldObj, Blocks.web, 0, 4, 6, 4, boundingbox);
		placeBlockAtCurrentPosition(worldObj, Blocks.web, 0, 4, 6, 5, boundingbox);
		placeBlockAtCurrentPosition(worldObj, Blocks.web, 0, 4, 6, 6, boundingbox);
		placeBlockAtCurrentPosition(worldObj, Blocks.web, 0, 5, 5, 2, boundingbox);
		placeBlockAtCurrentPosition(worldObj, Blocks.web, 0, 5, 5, 8, boundingbox);
		placeBlockAtCurrentPosition(worldObj, Blocks.web, 0, 5, 6, 2, boundingbox);
		placeBlockAtCurrentPosition(worldObj, Blocks.web, 0, 5, 6, 3, boundingbox);
		placeBlockAtCurrentPosition(worldObj, Blocks.web, 0, 5, 6, 4, boundingbox);
		placeBlockAtCurrentPosition(worldObj, Blocks.web, 0, 6, 5, 8, boundingbox);
		placeBlockAtCurrentPosition(worldObj, Blocks.web, 0, 6, 6, 2, boundingbox);
		placeBlockAtCurrentPosition(worldObj, Blocks.web, 0, 6, 6, 3, boundingbox);
		placeBlockAtCurrentPosition(worldObj, Blocks.web, 0, 6, 6, 7, boundingbox);
		placeBlockAtCurrentPosition(worldObj, Blocks.web, 0, 6, 6, 8, boundingbox);
		placeBlockAtCurrentPosition(worldObj, Blocks.web, 0, 7, 5, 8, boundingbox);
		placeBlockAtCurrentPosition(worldObj, Blocks.web, 0, 7, 6, 2, boundingbox);
		placeBlockAtCurrentPosition(worldObj, Blocks.web, 0, 7, 6, 8, boundingbox);
		placeBlockAtCurrentPosition(worldObj, Blocks.web, 0, 8, 5, 2, boundingbox);
		placeBlockAtCurrentPosition(worldObj, Blocks.web, 0, 8, 5, 3, boundingbox);
		placeBlockAtCurrentPosition(worldObj, Blocks.web, 0, 8, 5, 4, boundingbox);
		placeBlockAtCurrentPosition(worldObj, Blocks.web, 0, 8, 5, 5, boundingbox);
		placeBlockAtCurrentPosition(worldObj, Blocks.web, 0, 8, 5, 6, boundingbox);
		placeBlockAtCurrentPosition(worldObj, Blocks.web, 0, 8, 5, 8, boundingbox);
		placeBlockAtCurrentPosition(worldObj, Blocks.web, 0, 8, 6, 3, boundingbox);
		placeBlockAtCurrentPosition(worldObj, Blocks.web, 0, 8, 6, 6, boundingbox);

		for (int i = 0; i <= this.scatteredFeatureSizeX; ++i) {
			for (int j = 0; j <= this.scatteredFeatureSizeZ; ++j) {
				this.func_151554_b(worldObj, Blocks.cobblestone, 0, i, -1, j, boundingbox);
			}
		}
		this.fillWithMetadataBlocks(worldObj, boundingbox, 0, -1, 0, scatteredFeatureSizeX, -1, scatteredFeatureSizeY, Blocks.cobblestone, 0, Blocks.cobblestone, 0, false);

		placeBlockAtCurrentPosition(worldObj, Blocks.cobblestone_wall, 0, 1, 1, 4, boundingbox);
		placeBlockAtCurrentPosition(worldObj, Blocks.cobblestone_wall, 0, 1, 1, 6, boundingbox);
		placeBlockAtCurrentPosition(worldObj, Blocks.cobblestone_wall, 0, 1, 2, 4, boundingbox);
		placeBlockAtCurrentPosition(worldObj, Blocks.cobblestone_wall, 0, 1, 2, 6, boundingbox);
		placeBlockAtCurrentPosition(worldObj, Blocks.cobblestone_wall, 0, 1, 3, 4, boundingbox);
		placeBlockAtCurrentPosition(worldObj, Blocks.cobblestone_wall, 0, 1, 3, 6, boundingbox);

		ChestGenHooks info = ChestGenHooks.getInfo(MystObjects.MYST_TREASURE);
		this.hasMadeChest = this.generateStructureChestContents(worldObj, boundingbox, rand, 4, 1, 2, info.getItems(rand), info.getCount(rand));

		for (int i = 0; i < this.lecternGenned.length; ++i) {
			this.lecternGenned[i] = this.generateStructureLectern(worldObj, boundingbox, rand, lecternCoords[i][0], lecternCoords[i][1], lecternCoords[i][2], lecternTargs[i][0], lecternTargs[i][1], info);
		}

		return true;
	}

	protected boolean generateStructureLectern(World worldObj, StructureBoundingBox boundingbox, Random rand, int i, int j, int k, int i2, int k2, ChestGenHooks info) {
		int ti = this.getXWithOffset(i, k);
		int tj = this.getYWithOffset(j);
		int tk = this.getZWithOffset(i, k);

		int ti2 = this.getXWithOffset(i2, k2);
		int tk2 = this.getZWithOffset(i2, k2);

		if (boundingbox.isVecInside(ti, tj, tk)) {
			worldObj.setBlock(ti, tj, tk, ModBlocks.lectern);
			TileEntityLectern lectern = (TileEntityLectern) worldObj.getTileEntity(ti, tj, tk);

			if (lectern != null) {
				lectern.setYaw(360 - getRotation(ti, tk, ti2, tk2) + 270);
				ItemStack item = null;
				IAgeSymbol symbol = null;
				while (!lectern.isItemValidForSlot(0, item) || (symbol != null && (SymbolManager.getSymbolItemCardRank(symbol.identifier()) == null || SymbolManager.getSymbolItemCardRank(symbol.identifier()) < 3))) {
					item = info.getOneItem(rand); //TODO: (Treasure) Replace with better system?
					String symbolid = Page.getSymbol(item);
					if (symbolid == null) continue;
					symbol = SymbolManager.getAgeSymbol(symbolid);
				}
				if (item.stackSize > 0) item.stackSize = 1;
				lectern.setBook(item);
			}

			return true;
		}
		return false;
	}

	public static int getRotation(int i, int k, int i2, int k2) {
		int deltaX = i2 - i;
		int deltaZ = -(k2 - k);
		if (deltaZ == 0) return (deltaX < 0 ? 180 : 0);
		if (deltaX == 0) return (deltaZ < 0 ? 270 : 90);
		float f = (float) deltaZ / (float) deltaX;
		return (int) (Math.atan(f) * 180 / Math.PI);
	}
}
